Workbook

Sheet Warangal Cut Comparison
A1: WARANGAL REGION DEPOT SERVICE CUT ANALYSIS (LAST 30 DAYS)
A2: Layout: depot | predicted cut [service(count)] | actual cut [service(count)] | Source: warangal_cut_services_analysis.xlsx
A4: FORMAT 1: DEPOT-WISE PREDICTED VS ACTUAL CUT SERVICES (LAST 30 DAYS)
A5: depot | B5: predicted cut | C5: actual cut | D5: Difference (Act - Pred) | E5: Match %
A6: BHUPALAPALLAY | B6: HKL5(0) | C6: HKL5(24) | D6: 24 | E6: 0
B7: HNK7(0) | C7: HNK7(21) | D7: 21 | E7: 0
B8: PGD5(0) | C8: PGD5(19) | D8: 19 | E8: 0
B9: PBM3(0) | C9: PBM3(17) | D9: 17 | E9: 0
B10: BNR1(0) | C10: BNR1(8) | D10: 8 | E10: 0
A11: HANAMKONDA | B11: HKM2(14) | C11: HKM2(24) | D11: 10 | E11: 0.58333333
B12: 60C2(13) | C12: 60C2(22) | D12: 9 | E12: 0.59090909
B13: DPV1(6) | C13: DPV1(11) | D13: 5 | E13: 0.54545455
B14: 60C1(5) | C14: 60C1(21) | D14: 16 | E14: 0.23809524
B15: KNV1(5) | C15: KNV1(8) | D15: 3 | E15: 0.625
B16: 59C2(4) | C16: 59C2(20) | D16: 16 | E16: 0.2
B17: 59C1(2) | C17: 59C1(18) | D17: 16 | E17: 0.11111111
B18: 4JM2(1) | C18: 4JM2(8) | D18: 7 | E18: 0.125
A19: JANGAON | B19: HN13(11) | C19: HN13(7) | D19: -4 | E19: 0.63636364
B20: W193(1) | C20: W193(9) | D20: 8 | E20: 0.11111111
B21: JSB1(1) | C21: JSB1(8) | D21: 7 | E21: 0.125
A22: MAHABOOBABAD | B22: BDB2(9) | C22: BDB2(9) | D22: 0 | E22: 1
B23: BDB1(2) | C23: BDB1(9) | D23: 7 | E23: 0.22222222
B24: EY04(1) | C24: EY04(10) | D24: 9 | E24: 0.1
B25: GUM1(1) | C25: GUM1(3) | D25: 2 | E25: 0.33333333
A26: NARSAMPET | B26: ING2(11) | C26: ING2(20) | D26: 9 | E26: 0.55
A27: PARKAL | B27: GM03(13) | C27: GM03(23) | D27: 10 | E27: 0.56521739
B28: NP02(13) | C28: NP02(23) | D28: 10 | E28: 0.56521739
B29: LKV1(5) | C29: LKV1(8) | D29: 3 | E29: 0.625
A30: THORROR | B30: IBK1(17) | C30: IBK1(15) | D30: -2 | E30: 0.88235294
A31: WARANGAL-I | B31: HKW2(29) | C31: HKW2(14) | D31: -15 | E31: 0.48275862
B32: HRK1(29) | C32: HRK1(14) | D32: -15 | E32: 0.48275862
B33: HKW1(29) | C33: HKW1(13) | D33: -16 | E33: 0.44827586
B34: KRS1(11) | C34: KRS1(4) | D34: -7 | E34: 0.36363636
B35: KSO1(2) | C35: KSO1(8) | D35: 6 | E35: 0.25
A36: WARANGAL-II | B36: EK02(0) | C36: EK02(27) | D36: 27 | E36: 0
B37: EK07(0) | C37: EK07(27) | D37: 27 | E37: 0
B38: EK08(0) | C38: EK08(25) | D38: 25 | E38: 0
B39: ED17(0) | C39: ED17(22) | D39: 22 | E39: 0
B40: ES17(0) | C40: ES17(21) | D40: 21 | E40: 0
A43: FORMAT 2: HIGHEST COUNT OF CUTS & ACTUALS COMPARISON (PREDICTED SERVICES RANKED BY CUT VOLUME)
...

Sheet Summary
A1: EXECUTIVE SUMMARY: DEPOT PREDICTED VS ACTUAL SERVICE CUT REPORT
A2: Worksheet: warangal_cut_services_analysis.xlsx | Completed Window: 29 Days | Excluded Pending Dates: 2026-10-04 | Generated: 2026-10-27 11:40:50
A4: DELIVERABLE 1: OVERALL DEPOT-WISE CUT SUMMARY (Live Formulas Linked to Depot Sheets)
A5: Depot Name | B5: Completed Days | C5: Total Predicted Cuts | D5: Total Actual Cuts | E5: Difference (Actual - Predicted) | F5: Prediction Tracking Note
A6: BHUPALAPALLAY | B6: 29 | C6: ='BHUPALAPALLAY'!B46 | D6: ='BHUPALAPALLAY'!C46 | E6: =D6-C6 | F6: Zero AI predictions (Operational cuts only)
A7: HANAMKONDA | B7: 29 | C7: ='HANAMKONDA'!B103 | D7: ='HANAMKONDA'!C103 | E7: =D7-C7 | F7: High depot operational cuts beyond AI schedule
A8: JANGAON | B8: 29 | C8: ='JANGAON'!B59 | D8: ='JANGAON'!C59 | E8: =D8-C8 | F8: Standard AI predictions
A9: MAHABOOBABAD | B9: 29 | C9: ='MAHABOOBABAD'!B37 | D9: ='MAHABOOBABAD'!C37 | E9: =D9-C9 | F9: Standard AI predictions
A10: NARSAMPET | B10: 29 | C10: ='NARSAMPET'!B41 | D10: ='NARSAMPET'!C41 | E10: =D10-C10 | F10: Standard AI predictions
A11: PARKAL | B11: 29 | C11: ='PARKAL'!B42 | D11: ='PARKAL'!C42 | E11: =D11-C11 | F11: Standard AI predictions
A12: THORROR | B12: 29 | C12: ='THORROR'!B46 | D12: ='THORROR'!C46 | E12: =D12-C12 | F12: Standard AI predictions
A13: WARANGAL-I | B13: 29 | C13: ='WARANGAL-I'!B116 | D13: ='WARANGAL-I'!C116 | E13: =D13-C13 | F13: High depot operational cuts beyond AI schedule
A14: WARANGAL-II | B14: 29 | C14: ='WARANGAL-II'!B67 | D14: ='WARANGAL-II'!C67 | E14: =D14-C14 | F14: Zero AI predictions (Operational cuts only)
A15: Total | B15: =AVERAGE(B6:B14) | C15: =SUM(C6:C14) | D15: =SUM(D6:D14) | E15: =D15-C15 | F15: Consolidated Regional Cuts
A18: DELIVERABLE 2: REGULAR CUT SERVICES SUMMARY (Depot Cut on >= 10 Completed Days)
A19: Depot Name | B19: Regular Services Count | C19: Regular Predicted Cuts | D19: Regular Actual Cuts | E19: Difference (Act - Pred) | F19: Share of All Depot Cuts
A20: BHUPALAPALLAY | B20: 4 | C20: ='BHUPALAPALLAY'!F9 | D20: ='BHUPALAPALLAY'!G9 | E20: =D20-C20 | F20: =IF(D6>0, D20/D6, 0)
A21: HANAMKONDA | B21: 24 | C21: ='HANAMKONDA'!F29 | D21: ='HANAMKONDA'!G29 | E21: =D21-C21 | F21: =IF(D7>0, D21/D7, 0)
A22: JANGAON | B22: 7 | C22: ='JANGAON'!F12 | D22: ='JANGAON'!G12 | E22: =D22-C22 | F22: =IF(D8>0, D22/D8, 0)
A23: MAHABOOBABAD | B23: 5 | C23: ='MAHABOOBABAD'!F10 | D23: ='MAHABOOBABAD'!G10 | E23: =D23-C23 | F23: =IF(D9>0, D23/D9, 0)
A24: NARSAMPET | B24: 9 | C24: ='NARSAMPET'!F14 | D24: ='NARSAMPET'!G14 | E24: =D24-C24 | F24: =IF(D10>0, D24/D10, 0)
A25: PARKAL | B25: 8 | C25: ='PARKAL'!F13 | D25: ='PARKAL'!G13 | E25: =D25-C25 | F25: =IF(D11>0, D25/D11, 0)
A26: THORROR | B26: 4 | C26: ='THORROR'!F9 | D26: ='THORROR'!G9 | E26: =D26-C26 | F26: =IF(D12>0, D26/D12, 0)
A27: WARANGAL-I | B27: 29 | C27: ='WARANGAL-I'!F34 | D27: ='WARANGAL-I'!G34 | E27: =D27-C27 | F27: =IF(D13>0, D27/D13, 0)
A28: WARANGAL-II | B28: 24 | C28: ='WARANGAL-II'!F29 | D28: ='WARANGAL-II'!G29 | E28: =D28-C28 | F28: =IF(D14>0, D28/D14, 0)
A29: Total | B29: =SUM(B20:B28) | C29: =SUM(C20:C28) | D29: =SUM(D20:D28) | E29: =D29-C29 | F29: =IF(D15>0, D29/D15, 0)
A32: DELIVERABLE 3: CLOSE-MATCH PREDICTIONS SUMMARY (Pred >= 5 & Match Ratio >= 70%)
A33: Depot Name | B33: Close-Match Services | C33: Close-Match Predicted | D33: Close-Match Actual | E33: Difference (Act - Pred) | F33: Overall Match Ratio | G33: Same-Day Coincident Cuts
A34: BHUPALAPALLAY | B34: 0 | C34: 0 | D34: 0 | E34: 0 | F34: 0 | G34: 0
A35: HANAMKONDA | B35: 0 | C35: 0 | D35: 0 | E35: 0 | F35: 0 | G35: 0
A36: JANGAON | B36: 0 | C36: 0 | D36: 0 | E36: 0 | F36: 0 | G36: 0
A37: MAHABOOBABAD | B37: 1 | C37: ='MAHABOOBABAD'!K6 | D37: ='MAHABOOBABAD'!L6 | E37: =D37-C37 | F37: =IF(MAX(C37,D37)>0, MIN(C37,D37)/MAX(C37,D37), 0) | G37: ='MAHABOOBABAD'!O6
A38: NARSAMPET | B38: 0 | C38: 0 | D38: 0 | E38: 0 | F38: 0 | G38: 0
A39: PARKAL | B39: 0 | C39: 0 | D39: 0 | E39: 0 | F39: 0 | G39: 0
A40: THORROR | B40: 1 | C40: ='THORROR'!K6 | D40: ='THORROR'!L6 | E40: =D40-C40 | F40: =IF(MAX(C40,D40)>0, MIN(C40,D40)/MAX(C40,D40), 0) | G40: ='THORROR'!O6
A41: WARANGAL-I | B41: 0 | C41: 0 | D41: 0 | E41: 0 | F41: 0 | G41: 0
A42: WARANGAL-II | B42: 0 | C42: 0 | D42: 0 | E42: 0 | F42: 0 | G42: 0
A43: Total | B43: =SUM(B34:B42) | C43: =SUM(C34:C42) | D43: =SUM(D34:D42) | E43: =D43-C43 | F43: =IF(MAX(C43,D43)>0, MIN(C43,D43)/MAX(C43,D43), 0) | G43: =SUM(G34:G42)
A46: METHODOLOGY, COUNTING RULES & ADJUSTABLE THRESHOLDS
A47: 1. Data Structure & Service Parsing: Service codes are normalized and extracted from within parentheses. Non-cut columns are strictly ignored.
...

Sheet BHUPALAPALLAY
A1: DEPOT SERVICE CUT REPORT: BHUPALAPALLAY
A2: Period: Completed 29 Days (Like-for-Like Analysis) | Excluded Pending Dates: 2026-10-04 | Source: warangal_cut_services_analysis.xlsx
A3: DELIVERABLE 1: FULL CUT REPORT | E3: DELIVERABLE 2: REGULAR CUT SERVICES (Cut on >= 10 Completed Days) | J3: DELIVERABLE 3: CLOSE MATCH PREDICTIONS (Pred >= 5 & Match >= 70%)
A4: Service Number | B4: Predicted Cut Count | C4: Actual Cut Count | E4: Service Number | F4: Predicted Cut Count | G4: Actual Cut Count | H4: % of Days Cut | J4: Service Number | K4: Predicted Count | L4: Actual Count | M4: Difference (Act - Pred) | N4: Match % | O4: Same-Day Coincident Cuts
A5: ABK1 | B5: 0 | C5: 1 | E5: HKL5 | F5: 0 | G5: 24 | H5: =G5/29 | J5: No close matches qualified (or 0 predictions declared for depot)
A6: ABK4 | B6: 0 | C6: 4 | E6: HNK7 | F6: 0 | G6: 21 | H6: =G6/29
A7: BHK5 | B7: 0 | C7: 1 | E7: PGD5 | F7: 0 | G7: 19 | H7: =G7/29 | J7: NON-QUALIFYING PREDICTED SERVICES (Did not meet Deliverable 3 criteria)
A8: BKH1 | B8: 0 | C8: 1 | E8: PBM3 | F8: 0 | G8: 17 | H8: =G8/29 | J8: Service | K8: Pred Count | L8: Act Count | M8: Match % | N8: Same-Day Cuts | O8: Disqualification Reason
A9: BKH2 | B9: 0 | C9: 3 | E9: Total | F9: =SUM(F5:F8) | G9: =SUM(G5:G8) | H9: =G9/(29*COUNTA(E5:E8)) | J9: No predicted services or all predicted services qualified
A10: BNR1 | B10: 0 | C10: 8
A11: BPDP | B11: 0 | C11: 7
A12: BPKT | B12: 0 | C12: 4
A13: BSP1 | B13: 0 | C13: 5
A14: GDK9 | B14: 0 | C14: 1
A15: GDR2 | B15: 0 | C15: 5
A16: HCM3 | B16: 0 | C16: 8
A17: HKL1 | B17: 0 | C17: 1
A18: HKL5 | B18: 0 | C18: 24
A19: HKS1 | B19: 0 | C19: 2
A20: HKS2 | B20: 0 | C20: 1
A21: HKS3 | B21: 0 | C21: 1
... A45: SNG1 | B45: 0 | C45: 7
A46: Total | B46: =SUM(B5:B45) | C46: =SUM(C5:C45)

Sheet HANAMKONDA
A1: DEPOT SERVICE CUT REPORT: HANAMKONDA
A2: Period: Completed 29 Days (Like-for-Like Analysis) | Excluded Pending Dates: 2026-10-04 | Source: warangal_cut_services_analysis.xlsx
A3: DELIVERABLE 1: FULL CUT REPORT | E3: DELIVERABLE 2: REGULAR CUT SERVICES (Cut on >= 10 Completed Days) | J3: DELIVERABLE 3: CLOSE MATCH PREDICTIONS (Pred >= 5 & Match >= 70%)
A4: Service Number | B4: Predicted Cut Count | C4: Actual Cut Count | E4: Service Number | F4: Predicted Cut Count | G4: Actual Cut Count | H4: % of Days Cut | J4: Service Number | K4: Predicted Count | L4: Actual Count | M4: Difference (Act - Pred) | N4: Match % | O4: Same-Day Coincident Cuts
A5: 03C1 | B5: 0 | C5: 10 | E5: HKM2 | F5: 14 | G5: 24 | H5: =G5/29 | J5: No close matches qualified (or 0 predictions declared for depot)
A6: 05C1 | B6: 0 | C6: 2 | E6: HKM3 | F6: 0 | G6: 23 | H6: =G6/29
A7: 05C2 | B7: 0 | C7: 2 | E7: HKM5 | F7: 0 | G7: 23 | H7: =G7/29 | J7: NON-QUALIFYING PREDICTED SERVICES (Did not meet Deliverable 3 criteria)
A8: 06C2 | B8: 0 | C8: 1 | E8: 60C2 | F8: 13 | G8: 22 | H8: =G8/29 | J8: Service | K8: Pred Count | L8: Act Count | M8: Match % | N8: Same-Day Cuts | O8: Disqualification Reason
A9: 07C1 | B9: 0 | C9: 4 | E9: 60C1 | F9: 5 | G9: 21 | H9: =G9/29 | J9: HKM2 | K9: 14 | L9: 24 | M9: 0.58333333 | N9: 14 | O9: Match ratio 58.3% < 70%
A10: 07C2 | B10: 0 | C10: 5 | E10: 59C2 | F10: 4 | G10: 20 | H10: =G10/29 | J10: 60C2 | K10: 13 | L10: 22 | M10: 0.59090909 | N10: 9 | O10: Match ratio 59.1% < 70%
A11: 08S1 | B11: 0 | C11: 5 | E11: 59C1 | F11: 2 | G11: 18 | H11: =G11/29 | J11: DPV1 | K11: 6 | L11: 11 | M11: 0.54545455 | N11: 4 | O11: Match ratio 54.5% < 70%
A12: 08S2 | B12: 0 | C12: 5 | E12: 26C1 | F12: 0 | G12: 16 | H12: =G12/29 | J12: 60C1 | K12: 5 | L12: 21 | M12: 0.23809524 | N12: 3 | O12: Match ratio 23.8% < 70%
A13: 11C1 | B13: 0 | C13: 1 | E13: 67C1 | F13: 0 | G13: 16 | H13: =G13/29 | J13: KNV1 | K13: 5 | L13: 8 | M13: 0.625 | N13: 2 | O13: Match ratio 62.5% < 70%
A14: 11C2 | B14: 0 | C14: 2 | E14: 67C2 | F14: 0 | G14: 16 | H14: =G14/29 | J14: 59C2 | K14: 4 | L14: 20 | M14: 0.2 | N14: 2 | O14: Predicted < 5 times (4); Match ratio 20.0% < 70%
A15: 12H1 | B15: 0 | C15: 3 | E15: 58C1 | F15: 0 | G15: 15 | H15: =G15/29 | J15: 59C1 | K15: 2 | L15: 18 | M15: 0.11111111 | N15: 1 | O15: Predicted < 5 times (2); Match ratio 11.1% < 70%
A16: 14C1 | B16: 0 | C16: 5 | E16: 33C1 | F16: 0 | G16: 14 | H16: =G16/29 | J16: 4JM2 | K16: 1 | L16: 8 | M16: 0.125 | N16: 1 | O16: Predicted < 5 times (1); Match ratio 12.5% < 70%
A17: 14C2 | B17: 0 | C17: 5 | E17: 39C2 | F17: 0 | G17: 14 | H17: =G17/29
A18: 15C1 | B18: 0 | C18: 1 | E18: 66C2 | F18: 0 | G18: 14 | H18: =G18/29
A19: 15C2 | B19: 0 | C19: 1 | E19: 42C2 | F19: 0 | G19: 13 | H19: =G19/29
A20: 16C1 | B20: 0 | C20: 9 | E20: 4JG1 | F20: 0 | G20: 13 | H20: =G20/29
A21: 16C2 | B21: 0 | C21: 9 | E21: 42C1 | F21: 0 | G21: 12 | H21: =G21/29
A22: 18C1 | B22: 0 | C22: 8 | E22: 66C1 | F22: 0 | G22: 12 | H22: =G22/29
A23: 18C2 | B23: 0 | C23: 8 | E23: DPV1 | F23: 6 | G23: 11 | H23: =G23/29
A24: 19C1 | B24: 0 | C24: 2 | E24: 03C1 | F24: 0 | G24: 10 | H24: =G24/29
A25: 19C2 | B25: 0 | C25: 2 | E25: 27S2 | F25: 0 | G25: 10 | H25: =G25/29
A26: 1AN1 | B26: 0 | C26: 1 | E26: 34C1 | F26: 0 | G26: 10 | H26: =G26/29
A27: 20C1 | B27: 0 | C27: 1 | E27: 38C2 | F27: 0 | G27: 10 | H27: =G27/29
A28: 22C1 | B28: 0 | C28: 6 | E28: 50C2 | F28: 0 | G28: 10 | H28: =G28/29
A29: 22C2 | B29: 0 | C29: 5 | E29: Total | F29: =SUM(F5:F28) | G29: =SUM(G5:G28) | H29: =G29/(29*COUNTA(E5:E28))
A30: 23C1 | B30: 0 | C30: 5
A31: 23C2 | B31: 0 | C31: 6
A32: 24C1 | B32: 0 | C32: 1
A33: 24C2 | B33: 0 | C33: 3
A34: 24S1 | B34: 0 | C34: 6
A35: 26C1 | B35: 0 | C35: 16
A36: 27S2 | B36: 0 | C36: 10
A37: 28C2 | B37: 0 | C37: 1
A38: 29C1 | B38: 0 | C38: 3
A39: 2VW1 | B39: 0 | C39: 2
A40: 32C1 | B40: 0 | C40: 3
...

Sheet JANGAON
A1: DEPOT SERVICE CUT REPORT: JANGAON
A2: Period: Completed 29 Days (Like-for-Like Analysis) | Excluded Pending Dates: 2026-10-04 | Source: warangal_cut_services_analysis.xlsx
A3: DELIVERABLE 1: FULL CUT REPORT | E3: DELIVERABLE 2: REGULAR CUT SERVICES (Cut on >= 10 Completed Days) | J3: DELIVERABLE 3: CLOSE MATCH PREDICTIONS (Pred >= 5 & Match >= 70%)
A4: Service Number | B4: Predicted Cut Count | C4: Actual Cut Count | E4: Service Number | F4: Predicted Cut Count | G4: Actual Cut Count | H4: % of Days Cut | J4: Service Number | K4: Predicted Count | L4: Actual Count | M4: Difference (Act - Pred) | N4: Match % | O4: Same-Day Coincident Cuts
A5: 2SD1 | B5: 0 | C5: 2 | E5: H001 | F5: 0 | G5: 29 | H5: =G5/29 | J5: No close matches qualified (or 0 predictions declared for depot)
A6: B007 | B6: 0 | C6: 1 | E6: B013 | F6: 0 | G6: 28 | H6: =G6/29
A7: B013 | B7: 0 | C7: 28 | E7: B059 | F7: 0 | G7: 23 | H7: =G7/29 | J7: NON-QUALIFYING PREDICTED SERVICES (Did not meet Deliverable 3 criteria)
A8: B023 | B8: 0 | C8: 1 | E8: HN03 | F8: 0 | G8: 13 | H8: =G8/29 | J8: Service | K8: Pred Count | L8: Act Count | M8: Match % | N8: Same-Day Cuts | O8: Disqualification Reason
A9: B024 | B9: 0 | C9: 4 | E9: HN14 | F9: 0 | G9: 13 | H9: =G9/29 | J9: HN13 | K9: 11 | L9: 7 | M9: 0.63636364 | N9: 4 | O9: Match ratio 63.6% < 70%
A10: B026 | B10: 0 | C10: 4 | E10: HN02 | F10: 0 | G10: 12 | H10: =G10/29 | J10: JSB1 | K10: 1 | L10: 8 | M10: 0.125 | N10: 0 | O10: Predicted < 5 times (1); Match ratio 12.5% < 70%
A11: B029 | B11: 0 | C11: 2 | E11: JG07 | F11: 0 | G11: 12 | H11: =G11/29 | J11: W193 | K11: 1 | L11: 9 | M11: 0.11111111 | N11: 1 | O11: Predicted < 5 times (1); Match ratio 11.1% < 70%
A12: B059 | B12: 0 | C12: 23 | E12: Total | F12: =SUM(F5:F11) | G12: =SUM(G5:G11) | H12: =G12/(29*COUNTA(E5:E11))
A13: B163 | B13: 0 | C13: 1
A14: BBJ1 | B14: 0 | C14: 4
A15: BLJ1 | B15: 0 | C15: 1
A16: BPJ2 | B16: 0 | C16: 8
A17: BSJ1 | B17: 0 | C17: 7
A18: BSR1 | B18: 0 | C18: 5
A19: DDX1 | B19: 0 | C19: 7
A20: DPH3 | B20: 0 | C20: 1
A21: H001 | B21: 0 | C21: 29
A22: H124 | B22: 0 | C22: 1
A23: H202 | B23: 0 | C23: 1
A24: HN02 | B24: 0 | C24: 12
... A58: W910 | B58: 0 | C58: 7
A59: Total | B59: =SUM(B5:B58) | C59: =SUM(C5:C58)

Sheet MAHABOOBABAD
A1: DEPOT SERVICE CUT REPORT: MAHABOOBABAD
A2: Period: Completed 29 Days (Like-for-Like Analysis) | Excluded Pending Dates: 2026-10-04 | Source: warangal_cut_services_analysis.xlsx
A3: DELIVERABLE 1: FULL CUT REPORT | E3: DELIVERABLE 2: REGULAR CUT SERVICES (Cut on >= 10 Completed Days) | J3: DELIVERABLE 3: CLOSE MATCH PREDICTIONS (Pred >= 5 & Match >= 70%)
A4: Service Number | B4: Predicted Cut Count | C4: Actual Cut Count | E4: Service Number | F4: Predicted Cut Count | G4: Actual Cut Count | H4: % of Days Cut | J4: Service Number | K4: Predicted Count | L4: Actual Count | M4: Difference (Act - Pred) | N4: Match % | O4: Same-Day Coincident Cuts
A5: ASP8 | B5: 0 | C5: 1 | E5: KM20 | F5: 0 | G5: 28 | H5: =G5/29 | J5: BDB2 | K5: 9 | L5: 9 | M5: =L5-K5 | N5: =IF(MAX(K5,L5)>0, MIN(K5,L5)/MAX(K5,L5), 0) | O5: 4
A6: ATC1 | B6: 0 | C6: 2 | E6: BPL1 | F6: 0 | G6: 22 | H6: =G6/29 | J6: Total | K6: =SUM(K5:K5) | L6: =SUM(L5:L5) | M6: =L6-K6 | N6: =IF(MAX(K6,L6)>0, MIN(K6,L6)/MAX(K6,L6), 0) | O6: =SUM(O5:O5)
A7: BDB1 | B7: 2 | C7: 9 | E7: EY06 | F7: 0 | G7: 19 | H7: =G7/29
A8: BDB2 | B8: 9 | C8: 9 | E8: EY04 | F8: 1 | G8: 10 | H8: =G8/29 | J8: NON-QUALIFYING PREDICTED SERVICES (Did not meet Deliverable 3 criteria)
A9: BDB3 | B9: 0 | C9: 9 | E9: BDB4 | F9: 0 | G9: 10 | H9: =G9/29 | J9: Service | K9: Pred Count | L9: Act Count | M9: Match % | N9: Same-Day Cuts | O9: Disqualification Reason
A10: BDB4 | B10: 0 | C10: 10 | E10: Total | F10: =SUM(F5:F9) | G10: =SUM(G5:G9) | H10: =G10/(29*COUNTA(E5:E9)) | J10: BDB1 | K10: 2 | L10: 9 | M10: 0.22222222 | N10: 1 | O10: Predicted < 5 times (2); Match ratio 22.2% < 70%
A11: BPL1 | B11: 0 | C11: 22 | J11: EY04 | K11: 1 | L11: 10 | M11: 0.1 | N11: 0 | O11: Predicted < 5 times (1); Match ratio 10.0% < 70%
A12: CHG1 | B12: 0 | C12: 4 | J12: GUM1 | K12: 1 | L12: 3 | M12: 0.33333333 | N12: 0 | O12: Predicted < 5 times (1); Match ratio 33.3% < 70%
A13: DKL1 | B13: 0 | C13: 4
A14: DTH1 | B14: 0 | C14: 3
A15: DTH2 | B15: 0 | C15: 2
A16: EY02 | B16: 0 | C16: 1
A17: EY04 | B17: 1 | C17: 10
A18: EY06 | B18: 0 | C18: 19
A19: GPR1 | B19: 0 | C19: 4
A20: GUM1 | B20: 1 | C20: 3
A21: HYD1 | B21: 0 | C21: 1
A22: JGT2 | B22: 0 | C22: 1
A23: KM01 | B23: 0 | C23: 1
A24: KM05 | B24: 0 | C24: 1
... A36: YS01 | B36: 0 | C36: 4
A37: Total | B37: =SUM(B5:B36) | C37: =SUM(C5:C36)

Sheet NARSAMPET
A1: DEPOT SERVICE CUT REPORT: NARSAMPET
A2: Period: Completed 29 Days (Like-for-Like Analysis) | Excluded Pending Dates: 2026-10-04 | Source: warangal_cut_services_analysis.xlsx
A3: DELIVERABLE 1: FULL CUT REPORT | E3: DELIVERABLE 2: REGULAR CUT SERVICES (Cut on >= 10 Completed Days) | J3: DELIVERABLE 3: CLOSE MATCH PREDICTIONS (Pred >= 5 & Match >= 70%)
A4: Service Number | B4: Predicted Cut Count | C4: Actual Cut Count | E4: Service Number | F4: Predicted Cut Count | G4: Actual Cut Count | H4: % of Days Cut | J4: Service Number | K4: Predicted Count | L4: Actual Count | M4: Difference (Act - Pred) | N4: Match % | O4: Same-Day Coincident Cuts
A5: ASE1 | B5: 0 | C5: 1 | E5: KLM1 | F5: 0 | G5: 21 | H5: =G5/29 | J5: No close matches qualified (or 0 predictions declared for depot)
A6: BCM1 | B6: 0 | C6: 8 | E6: ING2 | F6: 11 | G6: 20 | H6: =G6/29
A7: BCM2 | B7: 0 | C7: 1 | E7: PKR1 | F7: 0 | G7: 17 | H7: =G7/29 | J7: NON-QUALIFYING PREDICTED SERVICES (Did not meet Deliverable 3 criteria)
A8: BRP1 | B8: 0 | C8: 4 | E8: YGT1 | F8: 0 | G8: 17 | H8: =G8/29 | J8: Service | K8: Pred Count | L8: Act Count | M8: Match % | N8: Same-Day Cuts | O8: Disqualification Reason
A9: DRP1 | B9: 0 | C9: 10 | E9: HNK1 | F9: 0 | G9: 16 | H9: =G9/29 | J9: ING2 | K9: 11 | L9: 20 | M9: 0.55 | N9: 8 | O9: Match ratio 55.0% < 70%
A10: HNE4 | B10: 0 | C10: 1 | E10: NLB2 | F10: 0 | G10: 12 | H10: =G10/29
A11: HNE6 | B11: 0 | C11: 1 | E11: MLG3 | F11: 0 | G11: 11 | H11: =G11/29
A12: HNK1 | B12: 0 | C12: 16 | E12: DRP1 | F12: 0 | G12: 10 | H12: =G12/29
A13: HT07 | B13: 0 | C13: 2 | E13: JP01 | F13: 0 | G13: 10 | H13: =G13/29
A14: HT08 | B14: 0 | C14: 3 | E14: Total | F14: =SUM(F5:F13) | G14: =SUM(G5:G13) | H14: =G14/(29*COUNTA(E5:E13))
A15: HT09 | B15: 0 | C15: 7
A16: ING2 | B16: 11 | C16: 20
A17: JP01 | B17: 0 | C17: 10
A18: KLM1 | B18: 0 | C18: 21
A19: MDR1 | B19: 0 | C19: 1
A20: MHB3 | B20: 0 | C20: 7
A21: MLG2 | B21: 0 | C21: 3
A22: MLG3 | B22: 0 | C22: 11
A23: MLG6 | B23: 0 | C23: 1
A24: NH01 | B24: 0 | C24: 2
A25: NH02 | B25: 0 | C25: 2
A26: NH04 | B26: 0 | C26: 2
... A40: YGT1 | B40: 0 | C40: 17
A41: Total | B41: =SUM(B5:B40) | C41: =SUM(C5:C40)

Sheet PARKAL
A1: DEPOT SERVICE CUT REPORT: PARKAL
A2: Period: Completed 29 Days (Like-for-Like Analysis) | Excluded Pending Dates: 2026-10-04 | Source: warangal_cut_services_analysis.xlsx
A3: DELIVERABLE 1: FULL CUT REPORT | E3: DELIVERABLE 2: REGULAR CUT SERVICES (Cut on >= 10 Completed Days) | J3: DELIVERABLE 3: CLOSE MATCH PREDICTIONS (Pred >= 5 & Match >= 70%)
A4: Service Number | B4: Predicted Cut Count | C4: Actual Cut Count | E4: Service Number | F4: Predicted Cut Count | G4: Actual Cut Count | H4: % of Days Cut | J4: Service Number | K4: Predicted Count | L4: Actual Count | M4: Difference (Act - Pred) | N4: Match % | O4: Same-Day Coincident Cuts
A5: BCM3 | B5: 0 | C5: 1 | E5: GM03 | F5: 13 | G5: 23 | H5: =G5/29 | J5: No close matches qualified (or 0 predictions declared for depot)
A6: BCM4 | B6: 0 | C6: 1 | E6: NP02 | F6: 13 | G6: 23 | H6: =G6/29
A7: GM01 | B7: 0 | C7: 2 | E7: PHN4 | F7: 0 | G7: 21 | H7: =G7/29 | J7: NON-QUALIFYING PREDICTED SERVICES (Did not meet Deliverable 3 criteria)
A8: GM03 | B8: 13 | C8: 23 | E8: PHK1 | F8: 0 | G8: 19 | H8: =G8/29 | J8: Service | K8: Pred Count | L8: Act Count | M8: Match % | N8: Same-Day Cuts | O8: Disqualification Reason
A9: GMH1 | B9: 0 | C9: 5 | E9: HP03 | F9: 0 | G9: 12 | H9: =G9/29 | J9: GM03 | K9: 13 | L9: 23 | M9: 0.56521739 | N9: 13 | O9: Match ratio 56.5% < 70%
A10: GPU1 | B10: 0 | C10: 1 | E10: ML04 | F10: 0 | G10: 12 | H10: =G10/29 | J10: NP02 | K10: 13 | L10: 23 | M10: 0.56521739 | N10: 13 | O10: Match ratio 56.5% < 70%
A11: HAB1 | B11: 0 | C11: 1 | E11: PAH6 | F11: 0 | G11: 12 | H11: =G11/29 | J11: LKV1 | K11: 5 | L11: 8 | M11: 0.625 | N11: 2 | O11: Match ratio 62.5% < 70%
A12: HAB2 | B12: 0 | C12: 3 | E12: HP02 | F12: 0 | G12: 10 | H12: =G12/29
A13: HP02 | B13: 0 | C13: 10 | E13: Total | F13: =SUM(F5:F12) | G13: =SUM(G5:G12) | H13: =G13/(29*COUNTA(E5:E12))
A14: HP03 | B14: 0 | C14: 12
A15: HP04 | B15: 0 | C15: 4
A16: HZ01 | B16: 0 | C16: 2
A17: HZ07 | B17: 0 | C17: 1
A18: KLS1 | B18: 0 | C18: 1
A19: LKV1 | B19: 5 | C19: 8
A20: MB01 | B20: 0 | C20: 1
A21: MB03 | B21: 0 | C21: 1
A22: ML04 | B22: 0 | C22: 12
A23: ML07 | B23: 0 | C23: 2
A24: NP01 | B24: 0 | C24: 1
A25: NP02 | B25: 13 | C25: 23
... A41: VK01 | B41: 0 | C41: 1
A42: Total | B42: =SUM(B5:B41) | C42: =SUM(C5:C41)

Sheet THORROR
A1: DEPOT SERVICE CUT REPORT: THORROR
A2: Period: Completed 29 Days (Like-for-Like Analysis) | Excluded Pending Dates: 2026-10-04 | Source: warangal_cut_services_analysis.xlsx
A3: DELIVERABLE 1: FULL CUT REPORT | E3: DELIVERABLE 2: REGULAR CUT SERVICES (Cut on >= 10 Completed Days) | J3: DELIVERABLE 3: CLOSE MATCH PREDICTIONS (Pred >= 5 & Match >= 70%)
A4: Service Number | B4: Predicted Cut Count | C4: Actual Cut Count | E4: Service Number | F4: Predicted Cut Count | G4: Actual Cut Count | H4: % of Days Cut | J4: Service Number | K4: Predicted Count | L4: Actual Count | M4: Difference (Act - Pred) | N4: Match % | O4: Same-Day Coincident Cuts
A5: AN02 | B5: 0 | C5: 1 | E5: WLO3 | F5: 0 | G5: 17 | H5: =G5/29 | J5: IBK1 | K5: 17 | L5: 15 | M5: =L5-K5 | N5: =IF(MAX(K5,L5)>0, MIN(K5,L5)/MAX(K5,L5), 0) | O5: 11
A6: BBD1 | B6: 0 | C6: 3 | E6: IBK1 | F6: 17 | G6: 15 | H6: =G6/29 | J6: Total | K6: =SUM(K5:K5) | L6: =SUM(L5:L5) | M6: =L6-K6 | N6: =IF(MAX(K6,L6)>0, MIN(K6,L6)/MAX(K6,L6), 0) | O6: =SUM(O5:O5)
A7: BBD5 | B7: 0 | C7: 1 | E7: WLO4 | F7: 0 | G7: 12 | H7: =G7/29
A8: HRJ1 | B8: 0 | C8: 4 | E8: PLJ1 | F8: 0 | G8: 10 | H8: =G8/29 | J8: NON-QUALIFYING PREDICTED SERVICES (Did not meet Deliverable 3 criteria)
A9: HSE3 | B9: 0 | C9: 6 | E9: Total | F9: =SUM(F5:F8) | G9: =SUM(G5:G8) | H9: =G9/(29*COUNTA(E5:E8)) | J9: Service | K9: Pred Count | L9: Act Count | M9: Match % | N9: Same-Day Cuts | O9: Disqualification Reason
A10: HSE4 | B10: 0 | C10: 3 | J10: No predicted services or all predicted services qualified
A11: IBK1 | B11: 17 | C11: 15
A12: JFD1 | B12: 0 | C12: 1
A13: JKO1 | B13: 0 | C13: 5
A14: KM10 | B14: 0 | C14: 2
A15: KM14 | B15: 0 | C15: 1
A16: KMH8 | B16: 0 | C16: 1
A17: KMO1 | B17: 0 | C17: 2
A18: KMO2 | B18: 0 | C18: 9
A19: KMO3 | B19: 0 | C19: 9
A20: KMO4 | B20: 0 | C20: 1
A21: MB05 | B21: 0 | C21: 1
A22: MB09 | B22: 0 | C22: 1
... A45: WLO4 | B45: 0 | C45: 12
A46: Total | B46: =SUM(B5:B45) | C46: =SUM(C5:C45)

Sheet WARANGAL-I
A1: DEPOT SERVICE CUT REPORT: WARANGAL-I
A2: Period: Completed 29 Days (Like-for-Like Analysis) | Excluded Pending Dates: 2026-10-04 | Source: warangal_cut_services_analysis.xlsx
A3: DELIVERABLE 1: FULL CUT REPORT | E3: DELIVERABLE 2: REGULAR CUT SERVICES (Cut on >= 10 Completed Days) | J3: DELIVERABLE 3: CLOSE MATCH PREDICTIONS (Pred >= 5 & Match >= 70%)
A4: Service Number | B4: Predicted Cut Count | C4: Actual Cut Count | E4: Service Number | F4: Predicted Cut Count | G4: Actual Cut Count | H4: % of Days Cut | J4: Service Number | K4: Predicted Count | L4: Actual Count | M4: Difference (Act - Pred) | N4: Match % | O4: Same-Day Coincident Cuts
A5: AKO3 | B5: 0 | C5: 21 | E5: MDR1 | F5: 0 | G5: 28 | H5: =G5/29 | J5: No close matches qualified (or 0 predictions declared for depot)
A6: BDE2 | B6: 0 | C6: 1 | E6: ENR1 | F6: 0 | G6: 27 | H6: =G6/29
A7: BDE9 | B7: 0 | C7: 1 | E7: MDR2 | F7: 0 | G7: 27 | H7: =G7/29 | J7: NON-QUALIFYING PREDICTED SERVICES (Did not meet Deliverable 3 criteria)
A8: BGL2 | B8: 0 | C8: 13 | E8: PLO3 | F8: 0 | G8: 27 | H8: =G8/29 | J8: Service | K8: Pred Count | L8: Act Count | M8: Match % | N8: Same-Day Cuts | O8: Disqualification Reason
A9: BLD1 | B9: 0 | C9: 4 | E9: HTN1 | F9: 0 | G9: 22 | H9: =G9/29 | J9: HKW1 | K9: 29 | L9: 13 | M9: 0.44827586 | N9: 13 | O9: Match ratio 44.8% < 70%
A10: BYH1 | B10: 0 | C10: 17 | E10: PSR1 | F10: 0 | G10: 22 | H10: =G10/29 | J10: HKW2 | K10: 29 | L10: 14 | M10: 0.48275862 | N10: 14 | O10: Match ratio 48.3% < 70%
A11: BYH2 | B11: 0 | C11: 1 | E11: SD18 | F11: 0 | G11: 22 | H11: =G11/29 | J11: HRK1 | K11: 29 | L11: 14 | M11: 0.48275862 | N11: 14 | O11: Match ratio 48.3% < 70%
A12: CTR1 | B12: 0 | C12: 1 | E12: AKO3 | F12: 0 | G12: 21 | H12: =G12/29 | J12: KRS1 | K12: 11 | L12: 4 | M12: 0.36363636 | N12: 0 | O12: Match ratio 36.4% < 70%
A13: DL10 | B13: 0 | C13: 3 | E13: MPT5 | F13: 0 | G13: 20 | H13: =G13/29 | J13: KSO1 | K13: 2 | L13: 8 | M13: 0.25 | N13: 1 | O13: Predicted < 5 times (2); Match ratio 25.0% < 70%
A14: DL11 | B14: 0 | C14: 11 | E14: DL12 | F14: 0 | G14: 19 | H14: =G14/29
A15: DL12 | B15: 0 | C15: 19 | E15: TGO6 | F15: 0 | G15: 18 | H15: =G15/29
A16: DLH1 | B16: 0 | C16: 2 | E16: BYH1 | F16: 0 | G16: 17 | H16: =G16/29
A17: DLH2 | B17: 0 | C17: 3 | E17: KKP4 | F17: 0 | G17: 17 | H17: =G17/29
A18: DLH3 | B18: 0 | C18: 4 | E18: KKP5 | F18: 0 | G18: 17 | H18: =G18/29
A19: DLH4 | B19: 0 | C19: 7 | E19: M112 | F19: 0 | G19: 17 | H19: =G19/29
A20: DLH5 | B20: 0 | C20: 8 | E20: HKW2 | F20: 29 | G20: 14 | H20: =G20/29
A21: DLH6 | B21: 0 | C21: 12 | E21: HRK1 | F21: 29 | G21: 14 | H21: =G21/29
A22: DLH7 | B22: 0 | C22: 3 | E22: HEN2 | F22: 0 | G22: 14 | H22: =G22/29
A23: DLH8 | B23: 0 | C23: 3 | E23: RJ34 | F23: 0 | G23: 14 | H23: =G23/29
A24: DLH9 | B24: 0 | C24: 7 | E24: SDO5 | F24: 0 | G24: 14 | H24: =G24/29
A25: ENR1 | B25: 0 | C25: 27 | E25: HKW1 | F25: 29 | G25: 13 | H25: =G25/29
... A33: HT02 | B33: 0 | C33: 4 | E33: RJ29 | F33: 0 | G33: 10 | H33: =G33/29
A34: HT04 | B34: 0 | C34: 4 | E34: Total | F34: =SUM(F5:F33) | G34: =SUM(G5:G33) | H34: =G34/(29*COUNTA(E5:E33))
A35: HT05 | B35: 0 | C35: 6
A36: HT06 | B36: 0 | C36: 2
A37: HT07 | B37: 0 | C37: 7
A38: HT08 | B38: 0 | C38: 2
A39: HT09 | B39: 0 | C39: 1
A40: HT10 | B40: 0 | C40: 2
A41: HT11 | B41: 0 | C41: 9
A42: HT12 | B42: 0 | C42: 2
A43: HT13 | B43: 0 | C43: 3
A44: HT14 | B44: 0 | C44: 6
A45: HT15 | B45: 0 | C45: 8
A46: HT46 | B46: 0 | C46: 1
... A115: VGO1 | B115: 0 | C115: 1
...

Sheet WARANGAL-II
A1: DEPOT SERVICE CUT REPORT: WARANGAL-II
A2: Period: Completed 29 Days (Like-for-Like Analysis) | Excluded Pending Dates: 2026-10-04 | Source: warangal_cut_services_analysis.xlsx
A3: DELIVERABLE 1: FULL CUT REPORT | E3: DELIVERABLE 2: REGULAR CUT SERVICES (Cut on >= 10 Completed Days) | J3: DELIVERABLE 3: CLOSE MATCH PREDICTIONS (Pred >= 5 & Match >= 70%)
A4: Service Number | B4: Predicted Cut Count | C4: Actual Cut Count | E4: Service Number | F4: Predicted Cut Count | G4: Actual Cut Count | H4: % of Days Cut | J4: Service Number | K4: Predicted Count | L4: Actual Count | M4: Difference (Act - Pred) | N4: Match % | O4: Same-Day Coincident Cuts
A5: BRK1 | B5: 0 | C5: 1 | E5: EK02 | F5: 0 | G5: 27 | H5: =G5/29 | J5: No close matches qualified (or 0 predictions declared for depot)
A6: ED02 | B6: 0 | C6: 2 | E6: EK07 | F6: 0 | G6: 27 | H6: =G6/29
A7: ED03 | B7: 0 | C7: 4 | E7: EK08 | F7: 0 | G7: 25 | H7: =G7/29 | J7: NON-QUALIFYING PREDICTED SERVICES (Did not meet Deliverable 3 criteria)
A8: ED04 | B8: 0 | C8: 5 | E8: ED17 | F8: 0 | G8: 22 | H8: =G8/29 | J8: Service | K8: Pred Count | L8: Act Count | M8: Match % | N8: Same-Day Cuts | O8: Disqualification Reason
A9: ED05 | B9: 0 | C9: 6 | E9: ES17 | F9: 0 | G9: 21 | H9: =G9/29 | J9: No predicted services or all predicted services qualified
A10: ED06 | B10: 0 | C10: 11 | E10: ES18 | F10: 0 | G10: 21 | H10: =G10/29
A11: ED07 | B11: 0 | C11: 12 | E11: ED16 | F11: 0 | G11: 20 | H11: =G11/29
A12: ED08 | B12: 0 | C12: 13 | E12: ES16 | F12: 0 | G12: 19 | H12: =G12/29
A13: ED10 | B13: 0 | C13: 4 | E13: ED15 | F13: 0 | G13: 18 | H13: =G13/29
A14: ED11 | B14: 0 | C14: 6 | E14: EK01 | F14: 0 | G14: 17 | H14: =G14/29
A15: ED12 | B15: 0 | C15: 9 | E15: EK03 | F15: 0 | G15: 17 | H15: =G15/29
A16: ED13 | B16: 0 | C16: 11 | E16: EK04 | F16: 0 | G16: 17 | H16: =G16/29
A17: ED14 | B17: 0 | C17: 13 | E17: EK06 | F17: 0 | G17: 17 | H17: =G17/29
A18: ED15 | B18: 0 | C18: 18 | E18: ES15 | F18: 0 | G18: 17 | H18: =G18/29
A19: ED16 | B19: 0 | C19: 20 | E19: ES14 | F19: 0 | G19: 16 | H19: =G19/29
A20: ED17 | B20: 0 | C20: 22 | E20: EK05 | F20: 0 | G20: 15 | H20: =G20/29
A21: ED40 | B21: 0 | C21: 1 | E21: ED08 | F21: 0 | G21: 13 | H21: =G21/29
... A28: EK01 | B28: 0 | C28: 17 | E28: KMR7 | F28: 0 | G28: 10 | H28: =G28/29
A29: EK02 | B29: 0 | C29: 27 | E29: Total | F29: =SUM(F5:F28) | G29: =SUM(G5:G28) | H29: =G29/(29*COUNTA(E5:E28))
A30: EK03 | B30: 0 | C30: 17
A31: EK04 | B31: 0 | C31: 17
A32: EK05 | B32: 0 | C32: 15
A33: EK06 | B33: 0 | C33: 17
A34: EK07 | B34: 0 | C34: 27
A35: EK08 | B35: 0 | C35: 25
A36: EM08 | B36: 0 | C36: 1
A37: EM10 | B37: 0 | C37: 1
A38: EM11 | B38: 0 | C38: 1
A39: EN02 | B39: 0 | C39: 1
A40: ER03 | B40: 0 | C40: 1
A41: ER05 | B41: 0 | C41: 1
... A66: MV03 | B66: 0 | C66: 2
A67: Total | B67: =SUM(B5:B66) | C67: =SUM(C5:C66)
